Workbook
Name note: 'For Manage'!$EI$3
Name TOP_CUSTOMER: Dataset!$AO$2:$AP$4

Sheet For Manage
A1: Thỏ Cáo 88 Vĩnh Phúc
B3: COMMISSION CALCULATOR
B6: SALES REPRESENTATIVE INFORMATION
B7: SALES REPRESENTATIVE'S NAME | E7: Sarah Brown | F7:  | G7: =IF(ISBLANK(E7),"*please write here","")
B9: HEAD OF SALES | E9: =IFERROR(INDEX('Employees '!A2:E32, MATCH(E11,'Employees '!E2:E32,0),2),"Not found") -> Emily Johnson
B10: REPORT TO | E10: =IFERROR(INDEX('Employees '!A2:E32, MATCH(E7,'Employees '!B2:B32,0),4),"Not found") -> John Smith
B11: COUNTRY | E11: =IFERROR(INDEX('Employees '!A2:E32, MATCH(E7,'Employees '!B2:B32,0),5),"Not found") -> USA
B12: CURRENCY | E12: =IFERROR(INDEX('Employees '!A2:F32, MATCH(E7,'Employees '!B2:B32,0),6),"Not found") -> USD
B14: CURRENT MONTH (example: January) | E14: April | F14:  | G14: =IF(ISBLANK(E14),"*please write here","")
B16: Balance in bank account up to the current month | E16: =G21*O33+G22*O41+G23*3+G24*O57 - G25 -> 186493.44 | F16: =E12 -> USD
B17: Foreign Exchange Rates | E17: =IFERROR(INDEX(Rates_to_USD[],MATCH(E11,Rates_to_USD[Country],0),2),0) -> 1
B19: TARGETS FOR EACH SALES REPRESENTATIVE
B20: Name of Target | E20: Target Value | F20: Commission Weights | G20: Commission Amount
B21: =_xlfn.CONCAT("Total Orders Value (",$E$12,")") -> Total Orders Value (USD) | E21: 1000000 | F21: 0.5 | G21: =$G$25*F21 -> 60000
B22: =_xlfn.CONCAT("Team total orders value achieved (",$E$12,")") -> Team total orders value achieved (USD) | E22: 10000000 | F22: 0.2 | G22: =$G$25*F22 -> 24000
B23: =_xlfn.CONCAT("Orders from Top Customers (",$E$12,")") -> Orders from Top Customers (USD) | E23: 250000 | F23: 0.1 | G23: =$G$25*F23 -> 12000
B24: =_xlfn.CONCAT("Orders from New Customers (",$E$12,")") -> Orders from New Customers (USD) | E24: 100000 | F24: 0.2 | G24: =$G$25*F24 -> 24000
B25: Total | F25: 1 | G25: 120000 | H25: ( according to contract )
B28: =_xlfn.CONCAT("1. TARGET: Total Orders Value (",$E$12,")") -> 1. TARGET: Total Orders Value (USD)
C30: January | D30: February | E30: March | F30: April | G30: May | H30: June | I30: July | J30: August | K30: September | L30: October | M30: November | N30: December | O30: TOTAL
B31: YTD result | C31: {=IFERROR(INDEX('For Employee'!$E$20:$P$22,1,1):INDEX('For Employee'!$E$20:$P$22,3,MONTH(DATEVALUE('For Manage'!$E$14&1))),"* Please click E7 and E14")} -> 379553.2 | D31: 731556.5 | E31: 1892629.1 | F31: 2568532.9 | O31: {=IFERROR(INDEX('For Employee'!$E$20:$P$22,1,MONTH(DATEVALUE('For Manage'!$E$14&1))),"0")} -> 2568532.9
B32: YTD achievement % | C32: 4.5546384 | D32: 4.389339 | E32: 7.5705162 | F32: 7.7055986 | O32: {=IFERROR(INDEX('For Employee'!$E$20:$P$22,2,MONTH(DATEVALUE('For Manage'!$E$14&1))),"0")} -> 7.7055986
B33: YTD Commission payment | C33: 3 | D33: 3 | E33: 3 | F33: 3 | O33: {=IFERROR(INDEX('For Employee'!$E$20:$P$22,3,MONTH(DATEVALUE('For Manage'!$E$14&1))),"0")} -> 3
B36: =_xlfn.CONCAT("2. TARGET: Team total orders value achieved (",$E$12,")") -> 2. TARGET: Team total orders value achieved (USD)
C38: January | D38: February | E38: March | F38: April | G38: May | H38: June | I38: July | J38: August | K38: September | L38: October | M38: November | N38: December | O38: TOTAL
B39: YTD result | C39: {=IFERROR(INDEX('For Employee'!$E$31:$P$33,1,1):INDEX('For Employee'!$E$31:$P$33,3,MONTH(DATEVALUE('For Manage'!$E$14&1))),"* Please click E7 and E14")} -> 379553.2 | D39: 731556.5 | E39: 1892629.1 | F39: 2568532.9 | O39: {=IFERROR(INDEX('For Employee'!$E$31:$P$33,1,MONTH(DATEVALUE('For Manage'!$E$14&1))),"0")} -> 2568532.9
B40: YTD achievement % | C40: 0.45546384 | D40: 0.4389339 | E40: 0.75705162 | F40: 0.77055986 | O40: {=IFERROR(INDEX('For Employee'!$E$31:$P$33,2,MONTH(DATEVALUE('For Manage'!$E$14&1))),"0")} -> 0.77055986
B41: YTD Commission payment | C41: 0 | D41: 0 | E41: 0.75705162 | F41: 0.77055986 | O41: {=IFERROR(INDEX('For Employee'!$E$31:$P$33,3,MONTH(DATEVALUE('For Manage'!$E$14&1))),"0")} -> 0.77055986
B44: =_xlfn.CONCAT("3. TARGET: Orders from Top Customers (",$E$12,")") -> 3. TARGET: Orders from Top Customers (USD)
C46: January | D46: February | E46: March | F46: April | G46: May | H46: June | I46: July | J46: August | K46: September | L46: October | M46: November | N46: December | O46: TOTAL
B47: YTD result | C47: {=IFERROR(INDEX('For Employee'!$E$41:$P$43,1,1):INDEX('For Employee'!$E$41:$P$43,3,MONTH(DATEVALUE('For Manage'!$E$14&1))),"* Please click E7 and E14")} -> 0 | D47: 150000 | E47: 150000 | F47: 150000 | O47: {=IFERROR(INDEX('For Employee'!$E$41:$P$43,1,MONTH(DATEVALUE('For Manage'!$E$14&1))),"0")} -> 150000
B48: YTD achievement % | C48: 0 | D48: 3.6 | E48: 2.4 | F48: 1.8 | O48: {=IFERROR(INDEX('For Employee'!$E$41:$P$43,2,MONTH(DATEVALUE('For Manage'!$E$14&1))),"0")} -> 1.8
B49: YTD Commission payment | C49: 0 | D49: 3 | E49: 3 | F49: 3 | O49: {=IFERROR(INDEX('For Employee'!$E$41:$P$43,3,MONTH(DATEVALUE('For Manage'!$E$14&1))),"0")} -> 3
B52: =_xlfn.CONCAT("4. TARGET: Orders from New Customers (",$E$12,")") -> 4. TARGET: Orders from New Customers (USD)
C54: January | D54: February | E54: March | F54: April | G54: May | H54: June | I54: July | J54: August | K54: September | L54: October | M54: November | N54: December | O54: TOTAL
B55: YTD result | C55: {=IFERROR(INDEX('For Employee'!$E$52:$P$54,1,1):INDEX('For Employee'!$E$52:$P$54,3,MONTH(DATEVALUE('For Manage'!$E$14&1))),"* Please click E7 and E14")} -> 29202.75 | D55: 229554.75 | E55: 539777.05 | F55: 765230.25 | O55: {=IFERROR(INDEX('For Employee'!$E$52:$P$54,1,MONTH(DATEVALUE('For Manage'!$E$14&1))),"0")} -> 765230.25
B56: YTD achievement % | C56: 3.50433 | D56: 13.773285 | E56: 21.591082 | F56: 22.956907 | O56: {=IFERROR(INDEX('For Employee'!$E$52:$P$54,2,MONTH(DATEVALUE('For Manage'!$E$14&1))),"0")} -> 22.956907
B57: YTD Commission payment | C57: 3 | D57: 3 | E57: 3 | F57: 3 | O57: {=IFERROR(INDEX('For Employee'!$E$52:$P$54,3,MONTH(DATEVALUE('For Manage'!$E$14&1))),"0")} -> 3
B61: Graphs to illustrate how Sarah's YTD result and the YTD target evolve in 2023
N69: TOTAL YEAR
...

Sheet For Employee
D3: COMMISSION CALCULATOR
G7: Name of Target | L7: Target Value | N7: Local Currency
G8: Total Orders Value (in Local Currency) | L8: ='For Manage'!E21 -> 1000000
G9: Team total orders value achieved (in Local Currency) | L9: ='For Manage'!E22 -> 10000000
G10: Orders from Top Customers (Value in Local Currency) | L10: ='For Manage'!E23 -> 250000 | P10: COUNTRY | Q10: ='For Manage'!E11 -> USA
G11: Orders from New Customers (Value in Local Currency) | L11: ='For Manage'!E24 -> 100000 | P11: CURRENCY | Q11: ='For Manage'!E12 -> USD
C13: 1.
D14: =_xlfn.CONCAT("TARGET: Total Orders Value (",$Q$11,")") -> TARGET: Total Orders Value (USD)
E16: January | F16: February | G16: March | H16: April | I16: May | J16: June | K16: July | L16: August | M16: September | N16: October | O16: November | P16: December | Q16: TOTAL
D17: MTD target | E17: =$Q$17/12 -> 83333.333 | F17: =$Q$17/12 -> 83333.333 | G17: =$Q$17/12 -> 83333.333 | H17: =$Q$17/12 -> 83333.333 | I17: =$Q$17/12 -> 83333.333 | J17: =$Q$17/12 -> 83333.333 | K17: =$Q$17/12 -> 83333.333 | L17: =$Q$17/12 -> 83333.333 | ... P17: =$Q$17/12 -> 83333.333 | Q17: =L8 -> 1000000
D18: YTD target | E18: =E17 -> 83333.333 | F18: =Table_2[[#This Row],[Column2]]+F17 -> 166666.67 | G18: =Table_2[[#This Row],[Column3]]+G17 -> 250000 | H18: =Table_2[[#This Row],[Column4]]+H17 -> 333333.33 | I18: =Table_2[[#This Row],[Column5]]+I17 -> 416666.67 | J18: =Table_2[[#This Row],[Column6]]+J17 -> 500000 | K18: =Table_2[[#This Row],[Column7]]+K17 -> 583333.33 | L18: =Table_2[[#This Row],[Column8]]+L17 -> 666666.67 | M18: =Table_2[[#This Row],[Column9]]+M17 -> 750000 | N18: =Table_2[[#This Row],[Column10]]+N17 -> 833333.33 | O18: =Table_2[[#This Row],[Column11]]+O17 -> 916666.67 | P18: =Table_2[[#This Row],[Column12]]+P17 -> 1000000
D19: MTD result | E19: =IFERROR(GETPIVOTDATA("Value of the Order",'Pivot Target 1'!$A$3,"Sales Rep",'For Manage'!$E$7,"Months (Order Date)",MONTH(DATEVALUE(E16&1)),"Years (Order Date)",TEXT(Dataset!$N$4, "yyy")),0) -> 379553.2 | F19: =IFERROR(GETPIVOTDATA("Value of the Order",'Pivot Target 1'!$A$3,"Sales Rep",'For Manage'!$E$7,"Months (Order Date)",MONTH(DATEVALUE(F16&1)),"Years (Order Date)",TEXT(Dataset!$N$4, "yyy")),0) -> 352003.3 | G19: =IFERROR(GETPIVOTDATA("Value of the Order",'Pivot Target 1'!$A$3,"Sales Rep",'For Manage'!$E$7,"Months (Order Date)",MONTH(DATEVALUE(G16&1)),"Years (Order Date)",TEXT(Dataset!$N$4, "yyy")),0) -> 1161072.6 | H19: =IFERROR(GETPIVOTDATA("Value of the Order",'Pivot Target 1'!$A$3,"Sales Rep",'For Manage'!$E$7,"Months (Order Date)",MONTH(DATEVALUE(H16&1)),"Years (Order Date)",TEXT(Dataset!$N$4, "yyy")),0) -> 675903.8 | I19: =IFERROR(GETPIVOTDATA("Value of the Order",'Pivot Target 1'!$A$3,"Sales Rep",'For Manage'!$E$7,"Months (Order Date)",MONTH(DATEVALUE(I16&1)),"Years (Order Date)",TEXT(Dataset!$N$4, "yyy")),0) -> 767153 | J19: =IFERROR(GETPIVOTDATA("Value of the Order",'Pivot Target 1'!$A$3,"Sales Rep",'For Manage'!$E$7,"Months (Order Date)",MONTH(DATEVALUE(J16&1)),"Years (Order Date)",TEXT(Dataset!$N$4, "yyy")),0) -> 1000352.2 | K19: =IFERROR(GETPIVOTDATA("Value of the Order",'Pivot Target 1'!$A$3,"Sales Rep",'For Manage'!$E$7,"Months (Order Date)",MONTH(DATEVALUE(K16&1)),"Years (Order Date)",TEXT(Dataset!$N$4, "yyy")),0) -> 279253.3 | L19: =IFERROR(GETPIVOTDATA("Value of the Order",'Pivot Target 1'!$A$3,"Sales Rep",'For Manage'!$E$7,"Months (Order Date)",MONTH(DATEVALUE(L16&1)),"Years (Order Date)",TEXT(Dataset!$N$4, "yyy")),0) -> 796752.65 | ... P19: =IFERROR(GETPIVOTDATA("Value of the Order",'Pivot Target 1'!$A$3,"Sales Rep",'For Manage'!$E$7,"Months (Order Date)",MONTH(DATEVALUE(P16&1)),"Years (Order Date)",TEXT(Dataset!$N$4, "yyy")),0) -> 896052.55 | Q19: =SUM(Table_2[[#This Row],[Column2]:[Column13]]) -> 7579055
D20: YTD result | E20: =SUM($E$19:E19) -> 379553.2 | F20: =SUM($E$19:F19) -> 731556.5 | G20: =SUM($E$19:G19) -> 1892629.1 | H20: =SUM($E$19:H19) -> 2568532.9 | I20: =SUM($E$19:I19) -> 3335685.9 | J20: =SUM($E$19:J19) -> 4336038 | K20: =SUM($E$19:K19) -> 4615291.3 | L20: =SUM($E$19:L19) -> 5412044 | ... P20: =SUM($E$19:P19) -> 7579055 | Q20: =Table_2[[#This Row],[Column13]] -> 7579055
D21: YTD achievement % | E21: =E20/E18 -> 4.5546384 | F21: =F20/F18 -> 4.389339 | G21: =G20/G18 -> 7.5705162 | H21: =H20/H18 -> 7.7055986 | I21: =I20/I18 -> 8.005646 | J21: =J20/J18 -> 8.6720761 | K21: =K20/K18 -> 7.911928 | L21: =L20/L18 -> 8.118066 | ... P21: =P20/P18 -> 7.579055 | Q21: =Table_2[[#This Row],[Column13]] -> 7.579055
D22: Commission payment | E22: =_xlfn.XLOOKUP(E21,'Xlookup Compensation scheme'!$Q$14:$Q$17,'Xlookup Compensation scheme'!D$14:D$17,,-1) -> 3 | F22: =_xlfn.XLOOKUP(F21,'Xlookup Compensation scheme'!$Q$14:$Q$17,'Xlookup Compensation scheme'!E$14:E$17,,-1) -> 3 | G22: =_xlfn.XLOOKUP(G21,'Xlookup Compensation scheme'!$Q$14:$Q$17,'Xlookup Compensation scheme'!F$14:F$17,,-1) -> 3 | H22: =_xlfn.XLOOKUP(H21,'Xlookup Compensation scheme'!$Q$14:$Q$17,'Xlookup Compensation scheme'!G$14:G$17,,-1) -> 3 | I22: =_xlfn.XLOOKUP(I21,'Xlookup Compensation scheme'!$Q$14:$Q$17,'Xlookup Compensation scheme'!H$14:H$17,,-1) -> 3 | J22: =_xlfn.XLOOKUP(J21,'Xlookup Compensation scheme'!$Q$14:$Q$17,'Xlookup Compensation scheme'!I$14:I$17,,-1) -> 3 | K22: =_xlfn.XLOOKUP(K21,'Xlookup Compensation scheme'!$Q$14:$Q$17,'Xlookup Compensation scheme'!J$14:J$17,,-1) -> 3 | L22: =_xlfn.XLOOKUP(L21,'Xlookup Compensation scheme'!$Q$14:$Q$17,'Xlookup Compensation scheme'!K$14:K$17,,-1) -> 3 | ... P22: =_xlfn.XLOOKUP(P21,'Xlookup Compensation scheme'!$Q$14:$Q$17,'Xlookup Compensation scheme'!O$14:O$17,,-1) -> 3 | Q22: =Table_2[[#This Row],[Column13]] -> 3
C24: 2.
D25: =_xlfn.CONCAT("TARGET: Team total orders value achieved (",$Q$11,")") -> TARGET: Team total orders value achieved (USD)
E27: January | F27: February | G27: March | H27: April | I27: May | J27: June | K27: July | L27: August | M27: September | N27: October | O27: November | P27: December | Q27: TOTAL
D28: MTD target | E28: =$Q$28/12 -> 833333.33 | F28: =$Q$28/12 -> 833333.33 | G28: =$Q$28/12 -> 833333.33 | H28: =$Q$28/12 -> 833333.33 | I28: =$Q$28/12 -> 833333.33 | J28: =$Q$28/12 -> 833333.33 | K28: =$Q$28/12 -> 833333.33 | L28: =$Q$28/12 -> 833333.33 | ... P28: =$Q$28/12 -> 833333.33 | Q28: =L9 -> 10000000
D29: YTD target | E29: =E28 -> 833333.33 | F29: =Table_39[[#This Row],[Column2]]+F28 -> 1666666.7 | G29: =Table_39[[#This Row],[Column3]]+G28 -> 2500000 | H29: =Table_39[[#This Row],[Column4]]+H28 -> 3333333.3 | I29: =Table_39[[#This Row],[Column5]]+I28 -> 4166666.7 | J29: =Table_39[[#This Row],[Column6]]+J28 -> 5000000 | K29: =Table_39[[#This Row],[Column7]]+K28 -> 5833333.3 | L29: =Table_39[[#This Row],[Column8]]+L28 -> 6666666.7 | M29: =Table_39[[#This Row],[Column9]]+M28 -> 7500000 | N29: =Table_39[[#This Row],[Column10]]+N28 -> 8333333.3 | O29: =Table_39[[#This Row],[Column11]]+O28 -> 9166666.7 | P29: =Table_39[[#This Row],[Column12]]+P28 -> 10000000
D30: MTD result | E30: =IFERROR(GETPIVOTDATA("Value of the Order",'Pivot Target 2'!$A$3,"Country",'For Manage'!$E$11,"Months (Order Date)",MONTH(DATEVALUE(E16&1)),"Years (Order Date)",TEXT(Dataset!$N$4, "yyy")),0) -> 379553.2 | F30: =IFERROR(GETPIVOTDATA("Value of the Order",'Pivot Target 2'!$A$3,"Country",'For Manage'!$E$11,"Months (Order Date)",MONTH(DATEVALUE(F16&1)),"Years (Order Date)",TEXT(Dataset!$N$4, "yyy")),0) -> 352003.3 | G30: =IFERROR(GETPIVOTDATA("Value of the Order",'Pivot Target 2'!$A$3,"Country",'For Manage'!$E$11,"Months (Order Date)",MONTH(DATEVALUE(G16&1)),"Years (Order Date)",TEXT(Dataset!$N$4, "yyy")),0) -> 1161072.6 | H30: =IFERROR(GETPIVOTDATA("Value of the Order",'Pivot Target 2'!$A$3,"Country",'For Manage'!$E$11,"Months (Order Date)",MONTH(DATEVALUE(H16&1)),"Years (Order Date)",TEXT(Dataset!$N$4, "yyy")),0) -> 675903.8 | I30: =IFERROR(GETPIVOTDATA("Value of the Order",'Pivot Target 2'!$A$3,"Country",'For Manage'!$E$11,"Months (Order Date)",MONTH(DATEVALUE(I16&1)),"Years (Order Date)",TEXT(Dataset!$N$4, "yyy")),0) -> 767153 | J30: =IFERROR(GETPIVOTDATA("Value of the Order",'Pivot Target 2'!$A$3,"Country",'For Manage'!$E$11,"Months (Order Date)",MONTH(DATEVALUE(J16&1)),"Years (Order Date)",TEXT(Dataset!$N$4, "yyy")),0) -> 1000352.2 | K30: =IFERROR(GETPIVOTDATA("Value of the Order",'Pivot Target 2'!$A$3,"Country",'For Manage'!$E$11,"Months (Order Date)",MONTH(DATEVALUE(K16&1)),"Years (Order Date)",TEXT(Dataset!$N$4, "yyy")),0) -> 279253.3 | L30: =IFERROR(GETPIVOTDATA("Value of the Order",'Pivot Target 2'!$A$3,"Country",'For Manage'!$E$11,"Months (Order Date)",MONTH(DATEVALUE(L16&1)),"Years (Order Date)",TEXT(Dataset!$N$4, "yyy")),0) -> 796752.65 | ... P30: =IFERROR(GETPIVOTDATA("Value of the Order",'Pivot Target 2'!$A$3,"Country",'For Manage'!$E$11,"Months (Order Date)",MONTH(DATEVALUE(P16&1)),"Years (Order Date)",TEXT(Dataset!$N$4, "yyy")),0) -> 896052.55 | Q30: =SUM(Table_39[[#This Row],[Column2]:[Column13]]) -> 7579055
D31: YTD result | E31: =SUM($E$30:E30) -> 379553.2 | F31: =SUM($E$30:F30) -> 731556.5 | G31: =SUM($E$30:G30) -> 1892629.1 | H31: =SUM($E$30:H30) -> 2568532.9 | I31: =SUM($E$30:I30) -> 3335685.9 | J31: =SUM($E$30:J30) -> 4336038 | K31: =SUM($E$30:K30) -> 4615291.3 | L31: =SUM($E$30:L30) -> 5412044 | ... P31: =SUM($E$30:P30) -> 7579055 | Q31: =Table_39[[#This Row],[Column13]] -> 7579055
D32: YTD achievement % | E32: =E31/E29 -> 0.45546384 | F32: =F31/F29 -> 0.4389339 | G32: =G31/G29 -> 0.75705162 | H32: =H31/H29 -> 0.77055986 | I32: =I31/I29 -> 0.8005646 | J32: =J31/J29 -> 0.86720761 | K32: =K31/K29 -> 0.7911928 | L32: =L31/L29 -> 0.8118066 | ... P32: =P31/P29 -> 0.7579055 | Q32: =Table_39[[#This Row],[Column13]] -> 0.7579055
D33: Commission payment | E33: =_xlfn.XLOOKUP(E32,'Xlookup Compensation scheme'!$Q$23:$Q$26,'Xlookup Compensation scheme'!D$23:D$26,,-1) -> 0 | F33: =_xlfn.XLOOKUP(F32,'Xlookup Compensation scheme'!$Q$23:$Q$26,'Xlookup Compensation scheme'!E$23:E$26,,-1) -> 0 | G33: =_xlfn.XLOOKUP(G32,'Xlookup Compensation scheme'!$Q$23:$Q$26,'Xlookup Compensation scheme'!F$23:F$26,,-1) -> 0.75705162 | H33: =_xlfn.XLOOKUP(H32,'Xlookup Compensation scheme'!$Q$23:$Q$26,'Xlookup Compensation scheme'!G$23:G$26,,-1) -> 0.77055986 | I33: =_xlfn.XLOOKUP(I32,'Xlookup Compensation scheme'!$Q$23:$Q$26,'Xlookup Compensation scheme'!H$23:H$26,,-1) -> 0.8005646 | J33: =_xlfn.XLOOKUP(J32,'Xlookup Compensation scheme'!$Q$23:$Q$26,'Xlookup Compensation scheme'!I$23:I$26,,-1) -> 0.86720761 | K33: =_xlfn.XLOOKUP(K32,'Xlookup Compensation scheme'!$Q$23:$Q$26,'Xlookup Compensation scheme'!J$23:J$26,,-1) -> 0.7911928 | L33: =_xlfn.XLOOKUP(L32,'Xlookup Compensation scheme'!$Q$23:$Q$26,'Xlookup Compensation scheme'!K$23:K$26,,-1) -> 0.8118066 | ... P33: =_xlfn.XLOOKUP(P32,'Xlookup Compensation scheme'!$Q$23:$Q$26,'Xlookup Compensation scheme'!O$23:O$26,,-1) -> 0.7579055 | Q33: =Table_39[[#This Row],[Column13]] -> 0.7579055
C34: 3.
D35: =_xlfn.CONCAT("TARGET: Orders from Top Customers (",$Q$11,")") -> TARGET: Orders from Top Customers (USD)
E37: January | F37: February | G37: March | H37: April | I37: May | J37: June | K37: July | L37: August | M37: September | N37: October | O37: November | P37: December | Q37: TOTAL
D38: MTD target | E38: =$Q$38/12 -> 20833.333 | F38: =$Q$38/12 -> 20833.333 | G38: =$Q$38/12 -> 20833.333 | H38: =$Q$38/12 -> 20833.333 | I38: =$Q$38/12 -> 20833.333 | J38: =$Q$38/12 -> 20833.333 | K38: =$Q$38/12 -> 20833.333 | L38: =$Q$38/12 -> 20833.333 | ... P38: =$Q$38/12 -> 20833.333 | Q38: =L10 -> 250000
D39: YTD target | E39: =E38 -> 20833.333 | F39: =Table_3[[#This Row],[Column2]]+F38 -> 41666.667 | G39: =Table_3[[#This Row],[Column3]]+G38 -> 62500 | H39: =Table_3[[#This Row],[Column4]]+H38 -> 83333.333 | I39: =Table_3[[#This Row],[Column5]]+I38 -> 104166.67 | J39: =Table_3[[#This Row],[Column6]]+J38 -> 125000 | K39: =Table_3[[#This Row],[Column7]]+K38 -> 145833.33 | L39: =Table_3[[#This Row],[Column8]]+L38 -> 166666.67 | M39: =Table_3[[#This Row],[Column9]]+M38 -> 187500 | N39: =Table_3[[#This Row],[Column10]]+N38 -> 208333.33 | O39: =Table_3[[#This Row],[Column11]]+O38 -> 229166.67 | P39: =Table_3[[#This Row],[Column12]]+P38 -> 250000
D40: MTD result | E40: =IFERROR(GETPIVOTDATA("Value of the Order",'Pivot Target 3'!$A$3,"Sales Rep",'For Manage'!$E$7,"Months (Order Date)",MONTH(DATEVALUE(E16&1)),"Years (Order Date)",TEXT(Dataset!$N$4, "yyy")),0) -> 0 | F40: =IFERROR(GETPIVOTDATA("Value of the Order",'Pivot Target 3'!$A$3,"Sales Rep",'For Manage'!$E$7,"Months (Order Date)",MONTH(DATEVALUE(F16&1)),"Years (Order Date)",TEXT(Dataset!$N$4, "yyy")),0) -> 150000 | G40: =IFERROR(GETPIVOTDATA("Value of the Order",'Pivot Target 3'!$A$3,"Sales Rep",'For Manage'!$E$7,"Months (Order Date)",MONTH(DATEVALUE(G16&1)),"Years (Order Date)",TEXT(Dataset!$N$4, "yyy")),0) -> 0 | H40: =IFERROR(GETPIVOTDATA("Value of the Order",'Pivot Target 3'!$A$3,"Sales Rep",'For Manage'!$E$7,"Months (Order Date)",MONTH(DATEVALUE(H16&1)),"Years (Order Date)",TEXT(Dataset!$N$4, "yyy")),0) -> 0 | I40: =IFERROR(GETPIVOTDATA("Value of the Order",'Pivot Target 3'!$A$3,"Sales Rep",'For Manage'!$E$7,"Months (Order Date)",MONTH(DATEVALUE(I16&1)),"Years (Order Date)",TEXT(Dataset!$N$4, "yyy")),0) -> 550550.85 | J40: =IFERROR(GETPIVOTDATA("Value of the Order",'Pivot Target 3'!$A$3,"Sales Rep",'For Manage'!$E$7,"Months (Order Date)",MONTH(DATEVALUE(J16&1)),"Years (Order Date)",TEXT(Dataset!$N$4, "yyy")),0) -> 0 | K40: =IFERROR(GETPIVOTDATA("Value of the Order",'Pivot Target 3'!$A$3,"Sales Rep",'For Manage'!$E$7,"Months (Order Date)",MONTH(DATEVALUE(K16&1)),"Years (Order Date)",TEXT(Dataset!$N$4, "yyy")),0) -> 250000 | L40: =IFERROR(GETPIVOTDATA("Value of the Order",'Pivot Target 3'!$A$3,"Sales Rep",'For Manage'!$E$7,"Months (Order Date)",MONTH(DATEVALUE(L16&1)),"Years (Order Date)",TEXT(Dataset!$N$4, "yyy")),0) -> 0 | ... P40: =IFERROR(GETPIVOTDATA("Value of the Order",'Pivot Target 3'!$A$3,"Sales Rep",'For Manage'!$E$7,"Months (Order Date)",MONTH(DATEVALUE(P16&1)),"Years (Order Date)",TEXT(Dataset!$N$4, "yyy")),0) -> 850000 | Q40: =SUM(Table_3[[#This Row],[Column2]:[Column13]]) -> 2150550.9
D41: YTD result | E41: =SUM($E$40:E40) -> 0 | F41: =SUM($E$40:F40) -> 150000 | G41: =SUM($E$40:G40) -> 150000 | H41: =SUM($E$40:H40) -> 150000 | I41: =SUM($E$40:I40) -> 700550.85 | J41: =SUM($E$40:J40) -> 700550.85 | K41: =SUM($E$40:K40) -> 950550.85 | L41: =SUM($E$40:L40) -> 950550.85 | ... P41: =SUM($E$40:P40) -> 2150550.9 | Q41: =Table_3[[#This Row],[Column13]] -> 2150550.9
D42: YTD achievement % | E42: =E41/E39 -> 0 | F42: =F41/F39 -> 3.6 | G42: =G41/G39 -> 2.4 | H42: =H41/H39 -> 1.8 | I42: =I41/I39 -> 6.7252882 | J42: =J41/J39 -> 5.6044068 | K42: =K41/K39 -> 6.518063 | L42: =L41/L39 -> 5.7033051 | ... P42: =P41/P39 -> 8.6022034 | Q42: =Table_3[[#This Row],[Column13]] -> 8.6022034
D43: Commission payment | E43: =_xlfn.XLOOKUP(E42,'Xlookup Compensation scheme'!$Q$33:$Q$35,'Xlookup Compensation scheme'!D$33:D$35,,-1) -> 0 | F43: =_xlfn.XLOOKUP(F42,'Xlookup Compensation scheme'!$Q$33:$Q$35,'Xlookup Compensation scheme'!E$33:E$35,,-1) -> 3 | G43: =_xlfn.XLOOKUP(G42,'Xlookup Compensation scheme'!$Q$33:$Q$35,'Xlookup Compensation scheme'!F$33:F$35,,-1) -> 3 | H43: =_xlfn.XLOOKUP(H42,'Xlookup Compensation scheme'!$Q$33:$Q$35,'Xlookup Compensation scheme'!G$33:G$35,,-1) -> 3 | I43: =_xlfn.XLOOKUP(I42,'Xlookup Compensation scheme'!$Q$33:$Q$35,'Xlookup Compensation scheme'!H$33:H$35,,-1) -> 3 | J43: =_xlfn.XLOOKUP(J42,'Xlookup Compensation scheme'!$Q$33:$Q$35,'Xlookup Compensation scheme'!I$33:I$35,,-1) -> 3 | K43: =_xlfn.XLOOKUP(K42,'Xlookup Compensation scheme'!$Q$33:$Q$35,'Xlookup Compensation scheme'!J$33:J$35,,-1) -> 3 | L43: =_xlfn.XLOOKUP(L42,'Xlookup Compensation scheme'!$Q$33:$Q$35,'Xlookup Compensation scheme'!K$33:K$35,,-1) -> 3 | ... P43: =_xlfn.XLOOKUP(P42,'Xlookup Compensation scheme'!$Q$33:$Q$35,'Xlookup Compensation scheme'!O$33:O$35,,-1) -> 3 | Q43: =Table_3[[#This Row],[Column13]] -> 3
C45: 4.
D46: =_xlfn.CONCAT("TARGET: Orders from New Customers (",$Q$11,")") -> TARGET: Orders from New Customers (USD)
E48: January | F48: February | G48: March | H48: April | I48: May | J48: June | K48: July | L48: August | M48: September | N48: October | O48: November | P48: December | Q48: TOTAL
D49: MTD target | E49: =$Q$49/12 -> 8333.3333 | F49: =$Q$49/12 -> 8333.3333 | G49: =$Q$49/12 -> 8333.3333 | H49: =$Q$49/12 -> 8333.3333 | I49: =$Q$49/12 -> 8333.3333 | J49: =$Q$49/12 -> 8333.3333 | K49: =$Q$49/12 -> 8333.3333 | L49: =$Q$49/12 -> 8333.3333 | ... P49: =$Q$49/12 -> 8333.3333 | Q49: =L11 -> 100000
D50: YTD target | E50: =E49 -> 8333.3333 | F50: =Table_4[[#This Row],[Column1]]+F49 -> 16666.667 | G50: =Table_4[[#This Row],[Column2]]+G49 -> 25000 | H50: =Table_4[[#This Row],[Column3]]+H49 -> 33333.333 | I50: =Table_4[[#This Row],[Column4]]+I49 -> 41666.667 | J50: =Table_4[[#This Row],[Column5]]+J49 -> 50000 | K50: =Table_4[[#This Row],[Column6]]+K49 -> 58333.333 | L50: =Table_4[[#This Row],[Column7]]+L49 -> 66666.667 | M50: =Table_4[[#This Row],[Column8]]+M49 -> 75000 | N50: =Table_4[[#This Row],[Column9]]+N49 -> 83333.333 | O50: =Table_4[[#This Row],[Column10]]+O49 -> 91666.667 | P50: =Table_4[[#This Row],[Column11]]+P49 -> 100000
D51: MTD result | E51: =IFERROR(GETPIVOTDATA("Value of the Order",'Pivot Target 4'!$A$3,"Sales Rep",'For Manage'!$E$7,"Months (Order Date)",MONTH(DATEVALUE(E16&1)),"Years (Order Date)",TEXT(Dataset!$N$4, "yyy")),0) -> 29202.75 | F51: =IFERROR(GETPIVOTDATA("Value of the Order",'Pivot Target 4'!$A$3,"Sales Rep",'For Manage'!$E$7,"Months (Order Date)",MONTH(DATEVALUE(F16&1)),"Years (Order Date)",TEXT(Dataset!$N$4, "yyy")),0) -> 200352 | G51: =IFERROR(GETPIVOTDATA("Value of the Order",'Pivot Target 4'!$A$3,"Sales Rep",'For Manage'!$E$7,"Months (Order Date)",MONTH(DATEVALUE(G16&1)),"Years (Order Date)",TEXT(Dataset!$N$4, "yyy")),0) -> 310222.3 | H51: =IFERROR(GETPIVOTDATA("Value of the Order",'Pivot Target 4'!$A$3,"Sales Rep",'For Manage'!$E$7,"Months (Order Date)",MONTH(DATEVALUE(H16&1)),"Years (Order Date)",TEXT(Dataset!$N$4, "yyy")),0) -> 225453.2 | I51: =IFERROR(GETPIVOTDATA("Value of the Order",'Pivot Target 4'!$A$3,"Sales Rep",'For Manage'!$E$7,"Months (Order Date)",MONTH(DATEVALUE(I16&1)),"Years (Order Date)",TEXT(Dataset!$N$4, "yyy")),0) -> 211101.4 | J51: =IFERROR(GETPIVOTDATA("Value of the Order",'Pivot Target 4'!$A$3,"Sales Rep",'For Manage'!$E$7,"Months (Order Date)",MONTH(DATEVALUE(J16&1)),"Years (Order Date)",TEXT(Dataset!$N$4, "yyy")),0) -> 49401.5 | K51: =IFERROR(GETPIVOTDATA("Value of the Order",'Pivot Target 4'!$A$3,"Sales Rep",'For Manage'!$E$7,"Months (Order Date)",MONTH(DATEVALUE(K16&1)),"Years (Order Date)",TEXT(Dataset!$N$4, "yyy")),0) -> 29002.5 | L51: =IFERROR(GETPIVOTDATA("Value of the Order",'Pivot Target 4'!$A$3,"Sales Rep",'For Manage'!$E$7,"Months (Order Date)",MONTH(DATEVALUE(L16&1)),"Years (Order Date)",TEXT(Dataset!$N$4, "yyy")),0) -> 45251.15 | ... P51: =IFERROR(GETPIVOTDATA("Value of the Order",'Pivot Target 4'!$A$3,"Sales Rep",'For Manage'!$E$7,"Months (Order Date)",MONTH(DATEVALUE(P16&1)),"Years (Order Date)",TEXT(Dataset!$N$4, "yyy")),0) -> 45201.9 | Q51: =SUM(Table_4[[#This Row],[Column1]:[Column12]]) -> 1221844.1
D52: YTD result | E52: =SUM($E$51:E51) -> 29202.75 | F52: =SUM($E$51:F51) -> 229554.75 | G52: =SUM($E$51:G51) -> 539777.05 | H52: =SUM($E$51:H51) -> 765230.25 | I52: =SUM($E$51:I51) -> 976331.65 | J52: =SUM($E$51:J51) -> 1025733.2 | K52: =SUM($E$51:K51) -> 1054735.6 | L52: =SUM($E$51:L51) -> 1099986.8 | ... P52: =SUM($E$51:P51) -> 1221844.1 | Q52: =Table_4[[#This Row],[Column12]] -> 1221844.1
...

Sheet Dataset
A1: Order Date | B1: Customer Name | C1: Country | D1: Region | E1: Value of the Order | F1: Order Type | G1: Sales Rep | H1: Transaction currency | I1: Sale Rep IS E7 | J1: Top Customers | K1: OLD/NEW customer | L1: Country IS E11 | N1: Sort Dataset => Get Currency Year. Maybe should get YEAR(MAX(Order Date))
A2: 44206 | B2: ABC Manufacturing | C2: USA | D2: NA | E2: 500000 | F2: Machine Order | G2: Sarah Brown | H2: USD | I2: =IF(Table_5[[#This Row],[Sales Rep]]='For Manage'!$E$7,1,0) -> 1 | J2: =IF(OR(Table_5[[#This Row],[Customer Name]]="ABC Manufacturing",Table_5[[#This Row],[Customer Name]]="123 Industries"), "Yes", "No") -> Yes | K2: =IF(COUNTIFS(Table_5[Customer Name],B2, Table_5[Order Date], ">="&DATE(2021,1,1), Table_5[Order Date], "<="&DATE(2022,12,31))>0, "Existing Customer", "New Customer") -> Existing Customer | L2: =IF(Table_5[[#This Row],[Country]]='For Manage'!$E$11,1,0) -> 1
A3: 44242 | B3: XYZ Corporation | C3: USA | D3: NA | E3: 700000 | F3: Normal Order | G3: Sarah Brown | H3: USD | I3: =IF(Table_5[[#This Row],[Sales Rep]]='For Manage'!$E$7,1,0) -> 1 | J3: =IF(OR(Table_5[[#This Row],[Customer Name]]="ABC Manufacturing",Table_5[[#This Row],[Customer Name]]="123 Industries"), "Yes", "No") -> No | K3: =IF(COUNTIFS(Table_5[Customer Name],B3, Table_5[Order Date], ">="&DATE(2021,1,1), Table_5[Order Date], "<="&DATE(2022,12,31))>0, "Existing Customer", "New Customer") -> Existing Customer | L3: =IF(Table_5[[#This Row],[Country]]='For Manage'!$E$11,1,0) -> 1 | N3: Order Date | O3: Customer Name | P3: Country | Q3: Region | R3: Value of the Order | S3: Order Type | T3: Sales Rep | U3: Transaction currency
A4: 44275 | B4: LMN Enterprises | C4: USA | D4: NA | E4: 300000 | F4: Service | G4: Sarah Brown | H4: USD | I4: =IF(Table_5[[#This Row],[Sales Rep]]='For Manage'!$E$7,1,0) -> 1 | J4: =IF(OR(Table_5[[#This Row],[Customer Name]]="ABC Manufacturing",Table_5[[#This Row],[Customer Name]]="123 Industries"), "Yes", "No") -> No | K4: =IF(COUNTIFS(Table_5[Customer Name],B4, Table_5[Order Date], ">="&DATE(2021,1,1), Table_5[Order Date], "<="&DATE(2022,12,31))>0, "Existing Customer", "New Customer") -> Existing Customer | L4: =IF(Table_5[[#This Row],[Country]]='For Manage'!$E$11,1,0) -> 1 | N4: {=_xlfn._xlws.SORT(Table_5[],1,-1)} -> 45277 | O4: ABC Manufacturing | P4: USA | Q4: NA | R4: 850000 | S4: Service | T4: Sarah Brown | U4: USD | V4: 1 | W4: Yes | X4: Existing Customer | Y4: 1
A5: 44291 | B5: 123 Industries | C5: USA | D5: NA | E5: 900000 | F5: Machine Order | G5: Sarah Brown | H5: USD | I5: =IF(Table_5[[#This Row],[Sales Rep]]='For Manage'!$E$7,1,0) -> 1 | J5: =IF(OR(Table_5[[#This Row],[Customer Name]]="ABC Manufacturing",Table_5[[#This Row],[Customer Name]]="123 Industries"), "Yes", "No") -> Yes | K5: =IF(COUNTIFS(Table_5[Customer Name],B5, Table_5[Order Date], ">="&DATE(2021,1,1), Table_5[Order Date], "<="&DATE(2022,12,31))>0, "Existing Customer", "New Customer") -> Existing Customer | L5: =IF(Table_5[[#This Row],[Country]]='For Manage'!$E$11,1,0) -> 1 | N5: 45277 | O5: Paulson Enterprises | P5: USA | Q5: NA | R5: 850.45 | S5: Service | T5: Sarah Brown | U5: USD | V5: 1 | W5: No | X5: New Customer | Y5: 1
A6: 44326 | B6: PQR Incorporated | C6: USA | D6: NA | E6: 400000 | F6: Normal Order | G6: Sarah Brown | H6: USD | I6: =IF(Table_5[[#This Row],[Sales Rep]]='For Manage'!$E$7,1,0) -> 1 | J6: =IF(OR(Table_5[[#This Row],[Customer Name]]="ABC Manufacturing",Table_5[[#This Row],[Customer Name]]="123 Industries"), "Yes", "No") -> No | K6: =IF(COUNTIFS(Table_5[Customer Name],B6, Table_5[Order Date], ">="&DATE(2021,1,1), Table_5[Order Date], "<="&DATE(2022,12,31))>0, "Existing Customer", "New Customer") -> Existing Customer | L6: =IF(Table_5[[#This Row],[Country]]='For Manage'!$E$11,1,0) -> 1 | N6: 45277 | O6: Martinez Solutions | P6: USA | Q6: NA | R6: 18500.25 | S6: Service | T6: Sarah Brown | U6: USD | V6: 1 | W6: No | X6: New Customer | Y6: 1
A7: 44362 | B7: ABC Manufacturing | C7: USA | D7: NA | E7: 600000 | F7: Service | G7: Sarah Brown | H7: USD | I7: =IF(Table_5[[#This Row],[Sales Rep]]='For Manage'!$E$7,1,0) -> 1 | J7: =IF(OR(Table_5[[#This Row],[Customer Name]]="ABC Manufacturing",Table_5[[#This Row],[Customer Name]]="123 Industries"), "Yes", "No") -> Yes | K7: =IF(COUNTIFS(Table_5[Customer Name],B7, Table_5[Order Date], ">="&DATE(2021,1,1), Table_5[Order Date], "<="&DATE(2022,12,31))>0, "Existing Customer", "New Customer") -> Existing Customer | L7: =IF(Table_5[[#This Row],[Country]]='For Manage'!$E$11,1,0) -> 1 | N7: 45277 | O7: Reed Corporation | P7: USA | Q7: NA | R7: 850.6 | S7: Service | T7: Sarah Brown | U7: USD | V7: 1 | W7: No | X7: New Customer | Y7: 1
A8: 44397 | B8: XYZ Corporation | C8: USA | D8: NA | E8: 800000 | F8: Machine Order | G8: Sarah Brown | H8: USD | I8: =IF(Table_5[[#This Row],[Sales Rep]]='For Manage'!$E$7,1,0) -> 1 | J8: =IF(OR(Table_5[[#This Row],[Customer Name]]="ABC Manufacturing",Table_5[[#This Row],[Customer Name]]="123 Industries"), "Yes", "No") -> No | K8: =IF(COUNTIFS(Table_5[Customer Name],B8, Table_5[Order Date], ">="&DATE(2021,1,1), Table_5[Order Date], "<="&DATE(2022,12,31))>0, "Existing Customer", "New Customer") -> Existing Customer | L8: =IF(Table_5[[#This Row],[Country]]='For Manage'!$E$11,1,0) -> 1 | N8: 45277 | O8: Reed Corporation | P8: USA | Q8: NA | R8: 25000.6 | S8: Service | T8: Sarah Brown | U8: USD | V8: 1 | W8: No | X8: New Customer | Y8: 1
A9: 44433 | B9: LMN Enterprises | C9: USA | D9: NA | E9: 200000 | F9: Normal Order | G9: Sarah Brown | H9: USD | I9: =IF(Table_5[[#This Row],[Sales Rep]]='For Manage'!$E$7,1,0) -> 1 | J9: =IF(OR(Table_5[[#This Row],[Customer Name]]="ABC Manufacturing",Table_5[[#This Row],[Customer Name]]="123 Industries"), "Yes", "No") -> No | K9: =IF(COUNTIFS(Table_5[Customer Name],B9, Table_5[Order Date], ">="&DATE(2021,1,1), Table_5[Order Date], "<="&DATE(2022,12,31))>0, "Existing Customer", "New Customer") -> Existing Customer | L9: =IF(Table_5[[#This Row],[Country]]='For Manage'!$E$11,1,0) -> 1 | N9: 45277 | O9: JKL Enterprises | P9: USA | Q9: NA | R9: 850.65 | S9: Service | T9: Sarah Brown | U9: USD | V9: 1 | W9: No | X9: Existing Customer | Y9: 1
A10: 44469 | B10: 123 Industries | C10: USA | D10: NA | E10: 1000000 | F10: Service | G10: Sarah Brown | H10: USD | I10: =IF(Table_5[[#This Row],[Sales Rep]]='For Manage'!$E$7,1,0) -> 1 | J10: =IF(OR(Table_5[[#This Row],[Customer Name]]="ABC Manufacturing",Table_5[[#This Row],[Customer Name]]="123 Industries"), "Yes", "No") -> Yes | K10: =IF(COUNTIFS(Table_5[Customer Name],B10, Table_5[Order Date], ">="&DATE(2021,1,1), Table_5[Order Date], "<="&DATE(2022,12,31))>0, "Existing Customer", "New Customer") -> Existing Customer | L10: =IF(Table_5[[#This Row],[Country]]='For Manage'!$E$11,1,0) -> 1 | N10: 45242 | O10: PQR Incorporated | P10: USA | Q10: NA | R10: 150000 | S10: Normal Order | T10: Sarah Brown | U10: USD | V10: 1 | W10: No | X10: Existing Customer | Y10: 1
A11: 44474 | B11: PQR Incorporated | C11: USA | D11: NA | E11: 550000 | F11: Machine Order | G11: Sarah Brown | H11: USD | I11: =IF(Table_5[[#This Row],[Sales Rep]]='For Manage'!$E$7,1,0) -> 1 | J11: =IF(OR(Table_5[[#This Row],[Customer Name]]="ABC Manufacturing",Table_5[[#This Row],[Customer Name]]="123 Industries"), "Yes", "No") -> No | K11: =IF(COUNTIFS(Table_5[Customer Name],B11, Table_5[Order Date], ">="&DATE(2021,1,1), Table_5[Order Date], "<="&DATE(2022,12,31))>0, "Existing Customer", "New Customer") -> Existing Customer | L11: =IF(Table_5[[#This Row],[Country]]='For Manage'!$E$11,1,0) -> 1 | N11: 45242 | O11: Harrison Corporation | P11: USA | Q11: NA | R11: 150.8 | S11: Normal Order | T11: Sarah Brown | U11: USD | V11: 1 | W11: No | X11: New Customer | Y11: 1
A12: 44510 | B12: ABC Manufacturing | C12: USA | D12: NA | E12: 450000 | F12: Normal Order | G12: Sarah Brown | H12: USD | I12: =IF(Table_5[[#This Row],[Sales Rep]]='For Manage'!$E$7,1,0) -> 1 | J12: =IF(OR(Table_5[[#This Row],[Customer Name]]="ABC Manufacturing",Table_5[[#This Row],[Customer Name]]="123 Industries"), "Yes", "No") -> Yes | K12: =IF(COUNTIFS(Table_5[Customer Name],B12, Table_5[Order Date], ">="&DATE(2021,1,1), Table_5[Order Date], "<="&DATE(2022,12,31))>0, "Existing Customer", "New Customer") -> Existing Customer | L12: =IF(Table_5[[#This Row],[Country]]='For Manage'!$E$11,1,0) -> 1 | N12: 45242 | O12: Wilson & Co. | P12: USA | Q12: NA | R12: 11500.75 | S12: Normal Order | T12: Sarah Brown | U12: USD | V12: 1 | W12: No | X12: New Customer | Y12: 1
A13: 44545 | B13: XYZ Corporation | C13: USA | D13: NA | E13: 350000 | F13: Service | G13: Sarah Brown | H13: USD | I13: =IF(Table_5[[#This Row],[Sales Rep]]='For Manage'!$E$7,1,0) -> 1 | J13: =IF(OR(Table_5[[#This Row],[Customer Name]]="ABC Manufacturing",Table_5[[#This Row],[Customer Name]]="123 Industries"), "Yes", "No") -> No | K13: =IF(COUNTIFS(Table_5[Customer Name],B13, Table_5[Order Date], ">="&DATE(2021,1,1), Table_5[Order Date], "<="&DATE(2022,12,31))>0, "Existing Customer", "New Customer") -> Existing Customer | L13: =IF(Table_5[[#This Row],[Country]]='For Manage'!$E$11,1,0) -> 1 | N13: 45242 | O13: Long Enterprises | P13: USA | Q13: NA | R13: 150.3 | S13: Normal Order | T13: Sarah Brown | U13: USD | V13: 1 | W13: No | X13: New Customer | Y13: 1
A14: 44581 | B14: LMN Enterprises | C14: USA | D14: NA | E14: 950000 | F14: Machine Order | G14: Sarah Brown | H14: USD | I14: =IF(Table_5[[#This Row],[Sales Rep]]='For Manage'!$E$7,1,0) -> 1 | J14: =IF(OR(Table_5[[#This Row],[Customer Name]]="ABC Manufacturing",Table_5[[#This Row],[Customer Name]]="123 Industries"), "Yes", "No") -> No | K14: =IF(COUNTIFS(Table_5[Customer Name],B14, Table_5[Order Date], ">="&DATE(2021,1,1), Table_5[Order Date], "<="&DATE(2022,12,31))>0, "Existing Customer", "New Customer") -> Existing Customer | L14: =IF(Table_5[[#This Row],[Country]]='For Manage'!$E$11,1,0) -> 1 | N14: 45242 | O14: Long Enterprises | P14: USA | Q14: NA | R14: 23000.3 | S14: Normal Order | T14: Sarah Brown | U14: USD | V14: 1 | W14: No | X14: New Customer | Y14: 1
A15: 44617 | B15: 123 Industries | C15: USA | D15: NA | E15: 250000 | F15: Normal Order | G15: Sarah Brown | H15: USD | I15: =IF(Table_5[[#This Row],[Sales Rep]]='For Manage'!$E$7,1,0) -> 1 | J15: =IF(OR(Table_5[[#This Row],[Customer Name]]="ABC Manufacturing",Table_5[[#This Row],[Customer Name]]="123 Industries"), "Yes", "No") -> Yes | K15: =IF(COUNTIFS(Table_5[Customer Name],B15, Table_5[Order Date], ">="&DATE(2021,1,1), Table_5[Order Date], "<="&DATE(2022,12,31))>0, "Existing Customer", "New Customer") -> Existing Customer | L15: =IF(Table_5[[#This Row],[Country]]='For Manage'!$E$11,1,0) -> 1 | N15: 45242 | O15: GHI Manufacturing | P15: USA | Q15: NA | R15: 150.75 | S15: Normal Order | T15: Sarah Brown | U15: USD | V15: 1 | W15: No | X15: Existing Customer | Y15: 1
A16: 44622 | B16: PQR Incorporated | C16: USA | D16: NA | E16: 750000 | F16: Service | G16: Sarah Brown | H16: USD | I16: =IF(Table_5[[#This Row],[Sales Rep]]='For Manage'!$E$7,1,0) -> 1 | J16: =IF(OR(Table_5[[#This Row],[Customer Name]]="ABC Manufacturing",Table_5[[#This Row],[Customer Name]]="123 Industries"), "Yes", "No") -> No | K16: =IF(COUNTIFS(Table_5[Customer Name],B16, Table_5[Order Date], ">="&DATE(2021,1,1), Table_5[Order Date], "<="&DATE(2022,12,31))>0, "Existing Customer", "New Customer") -> Existing Customer | L16: =IF(Table_5[[#This Row],[Country]]='For Manage'!$E$11,1,0) -> 1 | N16: 45206 | O16: 123 Industries | P16: USA | Q16: NA | R16: 350000 | S16: Machine Order | T16: Sarah Brown | U16: USD | V16: 1 | W16: Yes | X16: Existing Customer | Y16: 1
... A205: 44669 | B205: GHI Manufacturing | C205: USA | D205: NA | E205: 950 | F205: Machine Order | G205: Sarah Brown | H205: USD | I205: =IF(Table_5[[#This Row],[Sales Rep]]='For Manage'!$E$7,1,0) -> 1 | J205: =IF(OR(Table_5[[#This Row],[Customer Name]]="ABC Manufacturing",Table_5[[#This Row],[Customer Name]]="123 Industries"), "Yes", "No") -> No | K205: =IF(COUNTIFS(Table_5[Customer Name],B205, Table_5[Order Date], ">="&DATE(2021,1,1), Table_5[Order Date], "<="&DATE(2022,12,31))>0, "Existing Customer", "New Customer") -> Existing Customer | L205: =IF(Table_5[[#This Row],[Country]]='For Manage'!$E$11,1,0) -> 1 | N205: 44206 | O205: Johnson Industries | P205: USA | Q205: NA | R205: 5000.25 | S205: Machine Order | T205: Sarah Brown | U205: USD | V205: 1 | W205: No | X205: Existing Customer | Y205: 1
N206: 44206 | O206: Johnson & Sons | P206: USA | Q206: NA | R206: 500.5 | S206: Machine Order | T206: Sarah Brown | U206: USD | V206: 1 | W206: No | X206: Existing Customer | Y206: 1
N207: 44206 | O207: ABC Manufacturing | P207: USA | Q207: NA | R207: 500.25 | S207: Machine Order | T207: Sarah Brown | U207: USD | V207: 1 | W207: Yes | X207: Existing Customer | Y207: 1

Sheet Pivot Target 1
A1: Sale Rep IS E7 | B1: 1
A3: Sum of Value of the Order | B3: Column Labels
B4: 2023 | N4: 2023 Total | O4: 2022 | AA4: 2022 Total | AB4: 2021 | AN4: 2021 Total | AO4: Grand Total
A5: Row Labels | B5: Jan | C5: Feb | D5: Mar | E5: Apr | F5: May | G5: Jun | H5: Jul | I5: Aug | J5: Sep | K5: Oct | L5: Nov | M5: Dec | O5: Jan | P5: Feb | Q5: Mar | R5: Apr | S5: May | T5: Jun | U5: Jul | V5: Aug | W5: Sep | X5: Oct | Y5: Nov | Z5: Dec | AB5: Jan | AC5: Feb | AD5: Mar | AE5: Apr | AF5: May | AG5: Jun | AH5: Jul | AI5: Aug | AJ5: Sep | AK5: Oct | AL5: Nov | AM5: Dec
A6: Sarah Brown | B6: 379553.2 | C6: 352003.3 | D6: 1161072.6 | E6: 675903.8 | F6: 767153 | G6: 1000352.2 | H6: 279253.3 | I6: 796752.65 | J6: 697452.6 | K6: 388553 | L6: 184952.9 | M6: 896052.55 | N6: 7579055 | O6: 963252.35 | P6: 257803.15 | Q6: 762851.65 | R6: 862852 | S6: 151952.7 | T6: 658451.5 | U6: 455852.4 | V6: 557152.55 | W6: 962351.65 | X6: 253252.55 | Y6: 759752.75 | Z6: 658451.8 | AA6: 7303977 | AB6: 1006501 | AC6: 709102.75 | AD6: 306601.75 | AE6: 911702.4 | AF6: 405202.55 | AG6: 607801.3 | AH6: 810402.75 | AI6: 202603.2 | AJ6: 1013001.6 | AK6: 557152.05 | AL6: 455852.05 | AM6: 354552 | AN6: 7340475.4 | AO6: 22223508
A7: Grand Total | B7: 379553.2 | C7: 352003.3 | D7: 1161072.6 | E7: 675903.8 | F7: 767153 | G7: 1000352.2 | H7: 279253.3 | I7: 796752.65 | J7: 697452.6 | K7: 388553 | L7: 184952.9 | M7: 896052.55 | N7: 7579055 | O7: 963252.35 | P7: 257803.15 | Q7: 762851.65 | R7: 862852 | S7: 151952.7 | T7: 658451.5 | U7: 455852.4 | V7: 557152.55 | W7: 962351.65 | X7: 253252.55 | Y7: 759752.75 | Z7: 658451.8 | AA7: 7303977 | AB7: 1006501 | AC7: 709102.75 | AD7: 306601.75 | AE7: 911702.4 | AF7: 405202.55 | AG7: 607801.3 | AH7: 810402.75 | AI7: 202603.2 | AJ7: 1013001.6 | AK7: 557152.05 | AL7: 455852.05 | AM7: 354552 | AN7: 7340475.4 | AO7: 22223508

Sheet Pivot Target 2
A1: Country IS E11 | B1: 1
A3: Sum of Value of the Order | B3: Column Labels
B4: 2023 | N4: 2023 Total | O4: 2022 | AA4: 2022 Total | AB4: 2021 | AN4: 2021 Total | AO4: Grand Total
A5: Row Labels | B5: Jan | C5: Feb | D5: Mar | E5: Apr | F5: May | G5: Jun | H5: Jul | I5: Aug | J5: Sep | K5: Oct | L5: Nov | M5: Dec | O5: Jan | P5: Feb | Q5: Mar | R5: Apr | S5: May | T5: Jun | U5: Jul | V5: Aug | W5: Sep | X5: Oct | Y5: Nov | Z5: Dec | AB5: Jan | AC5: Feb | AD5: Mar | AE5: Apr | AF5: May | AG5: Jun | AH5: Jul | AI5: Aug | AJ5: Sep | AK5: Oct | AL5: Nov | AM5: Dec
A6: USA | B6: 379553.2 | C6: 352003.3 | D6: 1161072.6 | E6: 675903.8 | F6: 767153 | G6: 1000352.2 | H6: 279253.3 | I6: 796752.65 | J6: 697452.6 | K6: 388553 | L6: 184952.9 | M6: 896052.55 | N6: 7579055 | O6: 963252.35 | P6: 257803.15 | Q6: 762851.65 | R6: 862852 | S6: 151952.7 | T6: 658451.5 | U6: 455852.4 | V6: 557152.55 | W6: 962351.65 | X6: 253252.55 | Y6: 759752.75 | Z6: 658451.8 | AA6: 7303977 | AB6: 1006501 | AC6: 709102.75 | AD6: 306601.75 | AE6: 911702.4 | AF6: 405202.55 | AG6: 607801.3 | AH6: 810402.75 | AI6: 202603.2 | AJ6: 1013001.6 | AK6: 557152.05 | AL6: 455852.05 | AM6: 354552 | AN6: 7340475.4 | AO6: 22223508
A7: Grand Total | B7: 379553.2 | C7: 352003.3 | D7: 1161072.6 | E7: 675903.8 | F7: 767153 | G7: 1000352.2 | H7: 279253.3 | I7: 796752.65 | J7: 697452.6 | K7: 388553 | L7: 184952.9 | M7: 896052.55 | N7: 7579055 | O7: 963252.35 | P7: 257803.15 | Q7: 762851.65 | R7: 862852 | S7: 151952.7 | T7: 658451.5 | U7: 455852.4 | V7: 557152.55 | W7: 962351.65 | X7: 253252.55 | Y7: 759752.75 | Z7: 658451.8 | AA7: 7303977 | AB7: 1006501 | AC7: 709102.75 | AD7: 306601.75 | AE7: 911702.4 | AF7: 405202.55 | AG7: 607801.3 | AH7: 810402.75 | AI7: 202603.2 | AJ7: 1013001.6 | AK7: 557152.05 | AL7: 455852.05 | AM7: 354552 | AN7: 7340475.4 | AO7: 22223508

Sheet Pivot Target 3
A1: Top Customers | B1: Yes
A2: Sale Rep IS E7 | B2: 1
A4: Sum of Value of the Order | C4: Years (Order Date) | D4: Months (Order Date)
C5: 2023 | H5: 2023 Total | I5: 2022 | O5: 2022 Total | P5: 2021 | U5: 2021 Total | V5: Grand Total
A6: Sales Rep | B6: Customer Name | C6: Feb | D6: May | E6: Jul | F6: Oct | G6: Dec | I6: Feb | J6: Mar | K6: Apr | L6: Jul | M6: Sep | N6: Dec | P6: Jan | Q6: Apr | R6: Jun | S6: Sep | T6: Nov
A7: Sarah Brown | B7: 123 Industries | C7: 0 | D7: 550000 | E7: 0 | F7: 350000 | G7: 0 | H7: 900000 | I7: 250000 | J7: 0 | K7: 0 | L7: 450000 | M7: 0 | N7: 650000 | O7: 1350000 | P7: 0 | Q7: 900000 | R7: 0 | S7: 1000000 | T7: 0 | U7: 1900000 | V7: 4150000
B8: ABC Manufacturing | C8: 150000 | D8: 550.85 | E8: 250000 | F8: 0 | G8: 850000 | H8: 1250550.9 | I8: 0 | J8: 1400.75 | K8: 850000 | L8: 0 | M8: 950000 | N8: 0 | O8: 1801400.8 | P8: 1001000.2 | Q8: 0 | R8: 600000 | S8: 0 | T8: 450000 | U8: 2051000.2 | V8: 5102951.8
A9: Sarah Brown Total | C9: 150000 | D9: 550550.85 | E9: 250000 | F9: 350000 | G9: 850000 | H9: 2150550.9 | I9: 250000 | J9: 1400.75 | K9: 850000 | L9: 450000 | M9: 950000 | N9: 650000 | O9: 3151400.8 | P9: 1001000.2 | Q9: 900000 | R9: 600000 | S9: 1000000 | T9: 450000 | U9: 3951000.2 | V9: 9252951.8
A10: Grand Total | C10: 150000 | D10: 550550.85 | E10: 250000 | F10: 350000 | G10: 850000 | H10: 2150550.9 | I10: 250000 | J10: 1400.75 | K10: 850000 | L10: 450000 | M10: 950000 | N10: 650000 | O10: 3151400.8 | P10: 1001000.2 | Q10: 900000 | R10: 600000 | S10: 1000000 | T10: 450000 | U10: 3951000.2 | V10: 9252951.8

Sheet Pivot Target 4
A1: OLD/NEW customer | B1: New Customer
A2: Sale Rep IS E7 | B2: 1
A4: Sum of Value of the Order | C4: Years (Order Date) | D4: Months (Order Date)
C5: 2023 | O5: 2023 Total | P5: Grand Total
A6: Sales Rep | B6: Customer Name | C6: Jan | D6: Feb | E6: Mar | F6: Apr | G6: May | H6: Jun | I6: Jul | J6: Aug | K6: Sep | L6: Oct | M6: Nov | N6: Dec
A7: Sarah Brown | B7: Adams Ltd. | C7: 350.75 | D7: 0 | E7: 0 | F7: 0 | G7: 0 | H7: 0 | I7: 0 | J7: 0 | K7: 0 | L7: 0 | M7: 0 | N7: 0 | O7: 350.75 | P7: 350.75
B8: Baker & Sons | C8: 0 | D8: 0 | E8: 300871.6 | F8: 0 | G8: 0 | H8: 0 | I8: 0 | J8: 0 | K8: 0 | L8: 0 | M8: 0 | N8: 0 | O8: 300871.6 | P8: 300871.6
B9: Bell Corporation | C9: 0 | D9: 0 | E9: 0 | F9: 0 | G9: 0 | H9: 950.25 | I9: 0 | J9: 0 | K9: 0 | L9: 0 | M9: 0 | N9: 0 | O9: 950.25 | P9: 950.25
B10: Brown & Co. | C10: 0 | D10: 0 | E10: 0 | F10: 0 | G10: 0 | H10: 0 | I10: 2500.5 | J10: 0 | K10: 0 | L10: 0 | M10: 0 | N10: 0 | O10: 2500.5 | P10: 2500.5
B11: Carter Co. | C11: 0 | D11: 0 | E11: 0 | F11: 0 | G11: 550.9 | H11: 0 | I11: 0 | J11: 0 | K11: 0 | L11: 0 | M11: 0 | N11: 0 | O11: 550.9 | P11: 550.9
B12: Cole Co. | C12: 0 | D12: 0 | E12: 0 | F12: 0 | G12: 0 | H12: 0 | I12: 0 | J12: 0 | K12: 650.25 | L12: 0 | M12: 0 | N12: 0 | O12: 650.25 | P12: 650.25
B13: Cooper Group | C13: 0 | D13: 0 | E13: 0 | F13: 220501.9 | G13: 0 | H13: 0 | I13: 0 | J13: 0 | K13: 0 | L13: 0 | M13: 0 | N13: 0 | O13: 220501.9 | P13: 220501.9
B14: Davis & Sons | C14: 0 | D14: 0 | E14: 0 | F14: 0 | G14: 0 | H14: 0 | I14: 0 | J14: 0 | K14: 16500.5 | L14: 0 | M14: 0 | N14: 0 | O14: 16500.5 | P14: 16500.5
B15: Davis Solutions | C15: 3500.5 | D15: 0 | E15: 0 | F15: 0 | G15: 0 | H15: 0 | I15: 0 | J15: 0 | K15: 0 | L15: 0 | M15: 0 | N15: 0 | O15: 3500.5 | P15: 3500.5
B16: Evans Corporation | C16: 0 | D16: 200201.1 | E16: 0 | F16: 0 | G16: 0 | H16: 0 | I16: 0 | J16: 0 | K16: 0 | L16: 0 | M16: 0 | N16: 0 | O16: 200201.1 | P16: 200201.1
B17: Gray & Co. | C17: 0 | D17: 0 | E17: 0 | F17: 0 | G17: 210550.5 | H17: 0 | I17: 0 | J17: 0 | K17: 0 | L17: 0 | M17: 0 | N17: 0 | O17: 210550.5 | P17: 210550.5
B18: Hall Industries | C18: 25351.5 | D18: 0 | E18: 0 | F18: 0 | G18: 0 | H18: 0 | I18: 0 | J18: 0 | K18: 0 | L18: 0 | M18: 0 | N18: 0 | O18: 25351.5 | P18: 25351.5
B19: Harrison Corporation | C19: 0 | D19: 0 | E19: 0 | F19: 0 | G19: 0 | H19: 0 | I19: 0 | J19: 0 | K19: 0 | L19: 0 | M19: 150.8 | N19: 0 | O19: 150.8 | P19: 150.8
... B35: Wilson & Co. | C35: 0 | D35: 0 | E35: 0 | F35: 0 | G35: 0 | H35: 0 | I35: 0 | J35: 0 | K35: 0 | L35: 0 | M35: 11500.75 | N35: 0 | O35: 11500.75 | P35: 11500.75
A36: Sarah Brown Total | C36: 29202.75 | D36: 200352 | E36: 310222.3 | F36: 225453.2 | G36: 211101.4 | H36: 49401.5 | I36: 29002.5 | J36: 45251.15 | K36: 17150.75 | L36: 24702.5 | M36: 34802.15 | N36: 45201.9 | O36: 1221844.1 | P36: 1221844.1
A37: Grand Total | C37: 29202.75 | D37: 200352 | E37: 310222.3 | F37: 225453.2 | G37: 211101.4 | H37: 49401.5 | I37: 29002.5 | J37: 45251.15 | K37: 17150.75 | L37: 24702.5 | M37: 34802.15 | N37: 45201.9 | O37: 1221844.1 | P37: 1221844.1

Sheet Xlookup Compensation scheme
B3: COMMISSION CALCULATOR
B7: The Compensation scheme for each components
B10: A) The personal total orders value
C12: YTD achievement % | D12: ='For Employee'!E21 -> 4.5546384 | E12: ='For Employee'!F21 -> 4.389339 | F12: ='For Employee'!G21 -> 7.5705162 | G12: ='For Employee'!H21 -> 7.7055986 | H12: ='For Employee'!I21 -> 8.005646 | I12: ='For Employee'!J21 -> 8.6720761 | J12: ='For Employee'!K21 -> 7.911928 | K12: ='For Employee'!L21 -> 8.118066 | ... O12: ='For Employee'!P21 -> 7.579055
B14: 0<= E21 <= 0.5 | C14: thì E22 =0 | D14: 0 | E14: 0 | F14: 0 | G14: 0 | H14: 0 | I14: 0 | J14: 0 | K14: 0 | L14: 0 | M14: 0 | N14: 0 | O14: 0 | Q14: 0
B15: 0.5< E21 <= 1 | C15: thì E22 =E21 | D15: =D12 -> 4.5546384 | E15: =E12 -> 4.389339 | F15: =F12 -> 7.5705162 | G15: =G12 -> 7.7055986 | H15: =H12 -> 8.005646 | I15: =I12 -> 8.6720761 | J15: =J12 -> 7.911928 | K15: =K12 -> 8.118066 | ... O15: =O12 -> 7.579055 | Q15: 0.5
B16: 1< E21 < 2 | C16: thì E22 = (E21-1)*2+1 | D16: =(D12-1)*2+1 -> 8.1092768 | E16: =(E12-1)*2+1 -> 7.778678 | F16: =(F12-1)*2+1 -> 14.141032 | G16: =(G12-1)*2+1 -> 14.411197 | H16: =(H12-1)*2+1 -> 15.011292 | I16: =(I12-1)*2+1 -> 16.344152 | J16: =(J12-1)*2+1 -> 14.823856 | K16: =(K12-1)*2+1 -> 15.236132 | ... O16: =(O12-1)*2+1 -> 14.15811 | Q16: 1
B17: Max = | C17: 3 | D17: 3 | E17: =D17 -> 3 | F17: =E17 -> 3 | G17: =F17 -> 3 | H17: =G17 -> 3 | I17: =H17 -> 3 | J17: =I17 -> 3 | K17: =J17 -> 3 | L17: =K17 -> 3 | ... O17: =N17 -> 3 | Q17: 2
B19: B) Team total orders value
C21: YTD achievement % | D21: ='For Employee'!E32 -> 0.45546384 | E21: ='For Employee'!F32 -> 0.4389339 | F21: ='For Employee'!G32 -> 0.75705162 | G21: ='For Employee'!H32 -> 0.77055986 | H21: ='For Employee'!I32 -> 0.8005646 | I21: ='For Employee'!J32 -> 0.86720761 | J21: ='For Employee'!K32 -> 0.7911928 | K21: ='For Employee'!L32 -> 0.8118066 | ... O21: ='For Employee'!P32 -> 0.7579055
B23: 0<= E21 <= 0.5 | C23: thì E32 =0 | D23: 0 | E23: 0 | F23: 0 | G23: 0 | H23: 0 | I23: 0 | J23: 0 | K23: 0 | L23: 0 | M23: 0 | N23: 0 | O23: 0 | Q23: 0
B24: 0.5< E21 <= 1 | C24: thì E32 =E21 | D24: =D21 -> 0.45546384 | E24: =E21 -> 0.4389339 | F24: =F21 -> 0.75705162 | G24: =G21 -> 0.77055986 | H24: =H21 -> 0.8005646 | I24: =I21 -> 0.86720761 | J24: =J21 -> 0.7911928 | K24: =K21 -> 0.8118066 | ... O24: =O21 -> 0.7579055 | Q24: 0.5
B25: E21 > 1 | C25: thì E32 = (E21-1)*2+1 | D25: =(D21-1)*2+1 -> -0.08907232 | E25: =(E21-1)*2+1 -> -0.1221322 | F25: =(F21-1)*2+1 -> 0.51410324 | G25: =(G21-1)*2+1 -> 0.54111971 | H25: =(H21-1)*2+1 -> 0.60112921 | I25: =(I21-1)*2+1 -> 0.73441522 | J25: =(J21-1)*2+1 -> 0.58238561 | K25: =(K21-1)*2+1 -> 0.6236132 | ... O25: =(O21-1)*2+1 -> 0.51581101 | Q25: 1
B26: Max = | C26: 3 | D26: 3 | E26: =D26 -> 3 | F26: =E26 -> 3 | G26: =F26 -> 3 | H26: =G26 -> 3 | I26: =H26 -> 3 | J26: =I26 -> 3 | K26: =J26 -> 3 | L26: =K26 -> 3 | ... O26: =N26 -> 3 | Q26: 2
B29: C) Total orders from top customer
C31: YTD achievement % | D31: ='For Employee'!E42 -> 0 | E31: ='For Employee'!F42 -> 3.6 | F31: ='For Employee'!G42 -> 2.4 | G31: ='For Employee'!H42 -> 1.8 | H31: ='For Employee'!I42 -> 6.7252882 | I31: ='For Employee'!J42 -> 5.6044068 | J31: ='For Employee'!K42 -> 6.518063 | K31: ='For Employee'!L42 -> 5.7033051 | ... O31: ='For Employee'!P42 -> 8.6022034
B33: E42 <= 1 | C33: thì E43 = E42 | D33: =D31 -> 0 | E33: =E31 -> 3.6 | F33: =F31 -> 2.4 | G33: =G31 -> 1.8 | H33: =H31 -> 6.7252882 | I33: =I31 -> 5.6044068 | J33: =J31 -> 6.518063 | K33: =K31 -> 5.7033051 | ... O33: =O31 -> 8.6022034 | Q33: 0
B34: E42 > 1 | C34: thì E43 = (E42-1)*3+1 | D34: =(D31-1)*3+1 -> -2 | E34: =(E31-1)*3+1 -> 8.8 | F34: =(F31-1)*3+1 -> 5.2 | G34: =(G31-1)*3+1 -> 3.4 | H34: =(H31-1)*3+1 -> 18.175864 | I34: =(I31-1)*3+1 -> 14.81322 | J34: =(J31-1)*3+1 -> 17.554189 | K34: =(K31-1)*3+1 -> 15.109915 | ... O34: =(O31-1)*3+1 -> 23.80661 | Q34: 1
B35: Max = | C35: 3 | D35: 3 | E35: =D35 -> 3 | F35: =E35 -> 3 | G35: =F35 -> 3 | H35: =G35 -> 3 | I35: =H35 -> 3 | J35: =I35 -> 3 | K35: =J35 -> 3 | L35: =K35 -> 3 | ... O35: =N35 -> 3 | Q35: =(3-1)/3+1 -> 1.6666667
B38: D) Total orders from new customers
C40: YTD achievement % | D40: ='For Employee'!E53 -> 3.50433 | E40: ='For Employee'!F53 -> 13.773285 | F40: ='For Employee'!G53 -> 21.591082 | G40: ='For Employee'!H53 -> 22.956907 | H40: ='For Employee'!I53 -> 23.43196 | I40: ='For Employee'!J53 -> 20.514663 | J40: ='For Employee'!K53 -> 18.081183 | K40: ='For Employee'!L53 -> 16.499802 | ... O40: ='For Employee'!P53 -> 12.218441
B42: E53 <= 3 | C42: thì E54 = E53 | D42: =D40 -> 3.50433 | E42: =E40 -> 13.773285 | F42: =F40 -> 21.591082 | G42: =G40 -> 22.956907 | H42: =H40 -> 23.43196 | I42: =I40 -> 20.514663 | J42: =J40 -> 18.081183 | K42: =K40 -> 16.499802 | ... O42: =O40 -> 12.218441 | Q42: 0
B43: Max = | C43: 3 | D43: 3 | E43: =D43 -> 3 | F43: =E43 -> 3 | G43: =F43 -> 3 | H43: =G43 -> 3 | I43: =H43 -> 3 | J43: =I43 -> 3 | K43: =J43 -> 3 | L43: =K43 -> 3 | ... O43: =N43 -> 3 | Q43: 3

Sheet Employees 
A1: STT | B1: name | C1: positions | D1: report to | E1: country | F1: currency
A2: 1 | B2: Hans Schmidt | C2: Head of Sales | E2: Germany | F2: EUR | G2: =IF(ISNUMBER(SEARCH("rep", C2)), 1, "")
A3: 2 | B3: Anna Müller | C3: Sales Managers | D3: Hans Schmidt | E3: Germany | F3: EUR | G3: =IF(ISNUMBER(SEARCH("rep", C3)), 1, "") | I3: STT | J3: name | K3: positions | L3: report to | M3: country | N3: currency
A4: 3 | B4: Markus Wagner | C4: Sales Managers | D4: Hans Schmidt | E4: Germany | F4: EUR | G4: =IF(ISNUMBER(SEARCH("rep", C4)), 1, "") | I4: 5 | J4: Klaus Becker | K4: Sales Rep | L4: Anna Müller | M4: Germany | N4: EUR | O4: 1
A5: 4 | B5: Lena Fischer | C5: Sales Managers | D5: Hans Schmidt | E5: Germany | F5: EUR | G5: =IF(ISNUMBER(SEARCH("rep", C5)), 1, "") | I5: 6 | J5: Julia Schneider | K5: Sales Rep | L5: Anna Müller | M5: Germany | N5: EUR | O5: 1
A6: 5 | B6: Klaus Becker | C6: Sales Rep | D6: Anna Müller | E6: Germany | F6: EUR | G6: =IF(ISNUMBER(SEARCH("rep", C6)), 1, "") -> 1 | I6: 7 | J6: Stefan Weber | K6: Sales Rep | L6: Markus Wagner | M6: Germany | N6: EUR | O6: 1
A7: 6 | B7: Julia Schneider | C7: Sales Rep | D7: Anna Müller | E7: Germany | F7: EUR | G7: =IF(ISNUMBER(SEARCH("rep", C7)), 1, "") -> 1 | I7: 8 | J7: Petra Schulz | K7: Sales Rep | L7: Markus Wagner | M7: Germany | N7: EUR | O7: 1
A8: 7 | B8: Stefan Weber | C8: Sales Rep | D8: Markus Wagner | E8: Germany | F8: EUR | G8: =IF(ISNUMBER(SEARCH("rep", C8)), 1, "") -> 1 | I8: 9 | J8: Andreas Hoffmann | K8: Sales Rep | L8: Lena Fischer | M8: Germany | N8: EUR | O8: 1
A9: 8 | B9: Petra Schulz | C9: Sales Rep | D9: Markus Wagner | E9: Germany | F9: EUR | G9: =IF(ISNUMBER(SEARCH("rep", C9)), 1, "") -> 1 | I9: 10 | J9: Sabine Meyer | K9: Sales Rep | L9: Lena Fischer | M9: Germany | N9: EUR | O9: 1
A10: 9 | B10: Andreas Hoffmann | C10: Sales Rep | D10: Lena Fischer | E10: Germany | F10: EUR | G10: =IF(ISNUMBER(SEARCH("rep", C10)), 1, "") -> 1 | I10: 14 | J10: Sarah Brown | K10: Sales Rep | L10: John Smith | M10: USA | N10: USD | O10: 1
A11: 10 | B11: Sabine Meyer | C11: Sales Rep | D11: Lena Fischer | E11: Germany | F11: EUR | G11: =IF(ISNUMBER(SEARCH("rep", C11)), 1, "") -> 1 | I11: 15 | J11: David Jones | K11: Sales Rep | L11: John Smith | M11: USA | N11: USD | O11: 1
A12: 11 | B12: Emily Johnson | C12: Head of Sales | E12: USA | F12: USD | G12: =IF(ISNUMBER(SEARCH("rep", C12)), 1, "") | I12: 16 | J12: Jennifer Davis | K12: Sales Rep | L12: John Smith | M12: USA | N12: USD | O12: 1
A13: 12 | B13: John Smith | C13: Sales Managers | D13: Emily Johnson | E13: USA | F13: USD | G13: =IF(ISNUMBER(SEARCH("rep", C13)), 1, "") | I13: 17 | J13: James Miller | K13: Sales Rep | L13: John Smith | M13: USA | N13: USD | O13: 1
A14: 13 | B14: Michael Williams | C14: Sales Managers | D14: Emily Johnson | E14: USA | F14: USD | G14: =IF(ISNUMBER(SEARCH("rep", C14)), 1, "") | I14: 18 | J14: Amanda Wilson | K14: Sales Rep | L14: Michael Williams | M14: USA | N14: USD | O14: 1
A15: 14 | B15: Sarah Brown | C15: Sales Rep | D15: John Smith | E15: USA | F15: USD | G15: =IF(ISNUMBER(SEARCH("rep", C15)), 1, "") -> 1 | I15: 19 | J15: Robert Taylor | K15: Sales Rep | L15: Michael Williams | M15: USA | N15: USD | O15: 1
A16: 15 | B16: David Jones | C16: Sales Rep | D16: John Smith | E16: USA | F16: USD | G16: =IF(ISNUMBER(SEARCH("rep", C16)), 1, "") -> 1 | I16: 20 | J16: Jessica Martinez | K16: Sales Rep | L16: Michael Williams | M16: USA | N16: USD | O16: 1
A17: 16 | B17: Jennifer Davis | C17: Sales Rep | D17: John Smith | E17: USA | F17: USD | G17: =IF(ISNUMBER(SEARCH("rep", C17)), 1, "") -> 1 | I17: 22 | J17: Sofia Bianchi | K17: Sales Rep | L17: Giovanni Rossi | M17: Italy | N17: EUR | O17: 1
A18: 17 | B18: James Miller | C18: Sales Rep | D18: John Smith | E18: USA | F18: USD | G18: =IF(ISNUMBER(SEARCH("rep", C18)), 1, "") -> 1 | I18: 23 | J18: Marco Esposito | K18: Sales Rep | L18: Giovanni Rossi | M18: Italy | N18: EUR | O18: 1
A19: 18 | B19: Amanda Wilson | C19: Sales Rep | D19: Michael Williams | E19: USA | F19: USD | G19: =IF(ISNUMBER(SEARCH("rep", C19)), 1, "") -> 1 | I19: 24 | J19: Chiara Romano | K19: Sales Rep | L19: Giovanni Rossi | M19: Italy | N19: EUR | O19: 1
A20: 19 | B20: Robert Taylor | C20: Sales Rep | D20: Michael Williams | E20: USA | F20: USD | G20: =IF(ISNUMBER(SEARCH("rep", C20)), 1, "") -> 1 | I20: 25 | J20: Luca Ricci | K20: Sales Rep | L20: Giovanni Rossi | M20: Italy | N20: EUR | O20: 1
A21: 20 | B21: Jessica Martinez | C21: Sales Rep | D21: Michael Williams | E21: USA | F21: USD | G21: =IF(ISNUMBER(SEARCH("rep", C21)), 1, "") -> 1 | I21: 27 | J21: Aya Tanaka | K21: Sales Rep & Manager | L21: Takashi Nakamura | M21: Japan | N21: JPY | O21: 1
A22: 21 | B22: Giovanni Rossi | C22: Head of Sales | E22: Italy | F22: EUR | G22: =IF(ISNUMBER(SEARCH("rep", C22)), 1, "") | I22: 28 | J22: Kazuki Kobayashi | K22: Sales Rep & Manager | L22: Takashi Nakamura | M22: Japan | N22: JPY | O22: 1
A23: 22 | B23: Sofia Bianchi | C23: Sales Rep | D23: Giovanni Rossi | E23: Italy | F23: EUR | G23: =IF(ISNUMBER(SEARCH("rep", C23)), 1, "") -> 1 | I23: 29 | J23: Mio Sato | K23: Sales Rep & Manager | L23: Takashi Nakamura | M23: Japan | N23: JPY | O23: 1
A24: 23 | B24: Marco Esposito | C24: Sales Rep | D24: Giovanni Rossi | E24: Italy | F24: EUR | G24: =IF(ISNUMBER(SEARCH("rep", C24)), 1, "") -> 1 | I24: 30 | J24: Yusuke Takahashi | K24: Sales Rep | L24: Mio Sato | M24: Japan | N24: JPY | O24: 1
A25: 24 | B25: Chiara Romano | C25: Sales Rep | D25: Giovanni Rossi | E25: Italy | F25: EUR | G25: =IF(ISNUMBER(SEARCH("rep", C25)), 1, "") -> 1 | I25: 31 | J25: Sakura Ito | K25: Sales Rep | L25: Mio Sato | M25: Japan | N25: JPY | O25: 1
A26: 25 | B26: Luca Ricci | C26: Sales Rep | D26: Giovanni Rossi | E26: Italy | F26: EUR | G26: =IF(ISNUMBER(SEARCH("rep", C26)), 1, "") -> 1
A27: 26 | B27: Takashi Nakamura | C27: Head of Sales | E27: Japan | F27: JPY | G27: =IF(ISNUMBER(SEARCH("rep", C27)), 1, "")
A28: 27 | B28: Aya Tanaka | C28: Sales Rep & Manager | D28: Takashi Nakamura | E28: Japan | F28: JPY | G28: =IF(ISNUMBER(SEARCH("rep", C28)), 1, "") -> 1
A29: 28 | B29: Kazuki Kobayashi | C29: Sales Rep & Manager | D29: Takashi Nakamura | E29: Japan | F29: JPY | G29: =IF(ISNUMBER(SEARCH("rep", C29)), 1, "") -> 1
A30: 29 | B30: Mio Sato | C30: Sales Rep & Manager | D30: Takashi Nakamura | E30: Japan | F30: JPY | G30: =IF(ISNUMBER(SEARCH("rep", C30)), 1, "") -> 1
A31: 30 | B31: Yusuke Takahashi | C31: Sales Rep | D31: Mio Sato | E31: Japan | F31: JPY | G31: =IF(ISNUMBER(SEARCH("rep", C31)), 1, "") -> 1
A32: 31 | B32: Sakura Ito | C32: Sales Rep | D32: Mio Sato | E32: Japan | F32: JPY | G32: =IF(ISNUMBER(SEARCH("rep", C32)), 1, "") -> 1

Sheet 1 USD = 
A1: Country | B1: Rates | E1: 1 USD = 132.01 Japan
A2: AUSTRALIA | B2: 0.6683
A3: BRAZIL | B3: 5.2813
A4: CANADA | B4: 1.3753
A5: CHINA, P.R. | B5: 6.887
A6: DENMARK | B6: 6.9925
A7: EMU MEMBERS | B7: 1.0647
A8: HONG KONG | B8: 7.8493
A9: INDIA | B9: 82.56
A10: JAPAN | B10: 132.01
A11: MALAYSIA | B11: 4.484
A12: MEXICO | B12: 18.98
A13: NEW ZEALAND | B13: 0.6249
... A25: usa | B25: 1

Sheet Sheet14
A1: Sales Rep | B1: STT | C1: Customer Name
A2: Sarah Brown | B2: 1 | C2: Adams Ltd.
B3: 2 | C3: Baker & Sons
B4: 3 | C4: Bell Corporation
B5: 4 | C5: Brown & Co.
B6: 5 | C6: Carter Co.
B7: 6 | C7: Cole Co.
B8: 7 | C8: Cooper Group
B9: 8 | C9: Davis & Sons
B10: 9 | C10: Davis Solutions
B11: 10 | C11: Evans Corporation
B12: 11 | C12: Gray & Co.
B13: 12 | C13: Hall Industries
B14: 13 | C14: Harrison Corporation
... B30: 29 | C30: Wilson & Co.

Sheet Chart
A1: TARGET: Total Orders Value (in Local Currency)
B3: January | C3: February | D3: March | E3: April | F3: May | G3: June | H3: July | I3: August | J3: September | K3: October | L3: November | M3: December
A4: Fair | B4: 0.7 | C4: 0.7 | D4: 0.7 | E4: 0.7 | F4: 0.7 | G4: 0.7 | H4: 0.7 | I4: 0.7 | J4: 0.7 | K4: 0.7 | L4: 0.7 | M4: 0.7
A5: Good | B5: 0.8 | C5: 0.8 | D5: 0.8 | E5: 0.8 | F5: 0.8 | G5: 0.8 | H5: 0.8 | I5: 0.8 | J5: 0.8 | K5: 0.8 | L5: 0.8 | M5: 0.8
A6: Great | B6: 3.5 | C6: 3.5 | D6: 3.5 | E6: 3.5 | F6: 3.5 | G6: 3.5 | H6: 3.5 | I6: 3.5 | J6: 3.5 | K6: 3.5 | L6: 3.5 | M6: 3.5
